#옥타브의 에러 알림

옥타브는 프로그램의 오류를 두가지 방법으로 알려줍니다.

그 중 하나는 사용자가 입력한 것을 이해하지 못할 때 알려주는 *철자오류*입니다. 예를 들어, 사용자가 오타를 쳤을 경우

```octave:13> function y = f (x) y y = x***2; endfunction```

옥타브는 즉시 다음과 같은 메세지로 알려줍니다.

```
parse error:

  syntax error

>>> functiony = f (x) y = x***2; endfunction
                             ^
```

대부분의 철자오류의 경우, 사용자의 입력 중에서 알 수 없는 곳에 Caret('^')을 사용해서 알려줍니다. 예의 경우에는 자승(\*\*)에 철자오류가 있었기에 에러메세지를 보여줍니다. 코드는 거의 맞았지만 마지막 '*'가 어떤 의미인지 알 수 없기에 에러를 표시합니다.

다른 종류의 에러는 실행시에 일어납니다. 이런 오류를 *실행 시 오류* 혹은 *실행 오류*라고 합니다. 왜냐하면 이 오류는 사용자의 프로그램이 *실행*되거나 *계산 도중*에 일어나기 때문입니다. 예를 들어, 앞의 함수 정의의 실수를 고친 후에
```
octave:13> f ()
```
라고 입력하면, 옥타브는 다음과 같이 반응할 것입니다.
```
error: 'x' underfined near line 1 column 24
error: called from:
error:   f at line 1, column 22
```
이 에러메세지는 몇개의 부분으로 구성되어 있으며, 에러가 생긴 곳을 알려주는 몇몇 정보를 알려줍니다. 이 메세지는 내부 오류의 지점에서 생성되며, 첨부된 표현과 함수 호출의 추적을 제공합니다.

위의 예에서, 첫번째 줄에서는 어떤 함수나 표현식에서 첫번째 줄 24번째 열에서 'x'라는 정의되지 않은 변수가 발견되었다는 것을 지시합니다. 함수내에서 발생하는 에러는, 함수가 정의되어 있는 파일의 시작에서부터 줄을 세기 시작합니다. 포함된 함수 바깥에서 일어난 에러에서는 보통의 경우 주 프롬프트 문자열에서 표시된 입력 줄의 숫자를 의미합니다.

에러메세지의 두번째와 세번째 줄은 함수 `f`에서 일어난 에러라는 것을 의미합니다. 만일 함수 `f`가 다른 함수, 예를 들어 `g`에 의해서 호출되었다면, 에러 리스트는 또하나의 줄로 끝날 것입니다.

```
error:    g at line 1, column 17
```

이런 함수 호출의 리스트는 에러가 일어나기 전에 프로그램 어느 부분에서 에러가 일어났는 지 찾고 수정하기 편하도록 해줍니다.
